Workbook

Sheet Cover
A1: Adobe Inc. (NASDAQ: ADBE) — Equity Pitch
A2: LONG — the market is pricing an AI disruption that the filings do not show
A3: Archit Chawla · October 20, 2026 · All figures from SEC EDGAR filings unless noted; $ in millions except per-share
A5: Recommendation
A6: LONG / BUY
A7: Target price | B7: =Valuation!$B$37
A8: Price (close, Oct 19, 2026) | B8: =Assumptions!$B$5
A9: Implied upside | B9: =Valuation!$B$39
A10: Street consensus | B10: Hold, avg target $272–284 (stockanalysis.com / MarketBeat, Oct 20, 2026)
A12: Snapshot (LTM to Q3 FY2026)
A13: Revenue (LTM) | B13: =Historicals!J5
A14: Free cash flow (LTM) | B14: =Historicals!J25
A15: Buybacks (FY2025) | B15: =Historicals!G24
A16: Shares outstanding (Sep 18, 2026) | B16: =Assumptions!$B$6
A17: EV / LTM EBITDA | B17: =Valuation!$B$10
A18: P / LTM FCF | B18: =Valuation!$B$11
A20: Contents: Historicals (EDGAR inputs) · Assumptions (every driver, with rationale) · IS · CF_BS (linked three-statement forecast, FY2026E–FY2028E) · Valuation (DCF, scenarios, sensitivity, multiples history).
A21: Method in one line: FY2026E is built as 9M FY2026 actuals + a Q4 stub grown off Q4 FY2025; FY2027E–28E are driver-based; the balance sheet balances by construction and cash ties to the cash-flow statement in every year.
A22: Disclaimer: independent student research project prepared for educational purposes. Not investment advice. Verify all figures against the underlying SEC filings before acting on them.

Sheet Historicals
A1: Adobe Inc. (NASDAQ: ADBE) — Historical Financials
A2: Source: SEC EDGAR company facts (CIK 0000796343), pulled 2026-10-20 via pull_data.py. Adobe's fiscal year ends the Friday nearest Nov 30 (FY2025 ended Nov 28, 2025). $ in millions; shares in millions. LTM = FY2025 − 9M FY2025 + 9M FY2026 (live formulas).
B4: EDGAR concept | C4: FY2021 | D4: FY2022 | E4: FY2023 | F4: FY2024 | G4: FY2025 | H4: 9M FY2025 | I4: 9M FY2026 | J4: LTM to Q3 FY26 | K4: Latest BS — Q3 FY26 (Aug 28, 2026)
A5: Revenue | B5: Revenues | C5: 15785 | D5: 17606 | E5: 19409 | F5: 21505 | G5: 23769 | H5: 17575 | I5: 19776 | J5: =G5-H5+I5
A6: Cost of revenue | B6: CostOfRevenue | C6: 1865 | D6: 2165 | E6: 2354 | F6: 2358 | G6: 2551 | H6: 1902 | I6: 2142 | J6: =G6-H6+I6
A7: Gross profit | B7: GrossProfit | C7: 13920 | D7: 15441 | E7: 17055 | F7: 19147 | G7: 21218 | H7: 15673 | I7: 17634 | J7: =G7-H7+I7
A8: Research & development | B8: ResearchAndDevelopmentExpense (software) | C8: 2540 | D8: 2987 | E8: 3473 | F8: 3944 | G8: 4294 | H8: 3196 | I8: 3596 | J8: =G8-H8+I8
A9: Sales & marketing | B9: SellingAndMarketingExpense | C9: 4321 | D9: 4968 | E9: 5351 | F9: 5764 | G9: 6488 | H9: 4760 | I9: 5419 | J9: =G9-H9+I9
A10: General & administrative | B10: GeneralAndAdministrativeExpense | C10: 1085 | D10: 1219 | E10: 1413 | F10: 1529 | G10: 1573 | H10: 1152 | I10: 1497 | J10: =G10-H10+I10
A11: Amortization of acquired intangibles | B11: Derived: OperatingExpenses − R&D − S&M − G&A | C11: 172 | D11: 169 | E11: 168 | F11: 1169 | G11: 157 | H11: 120 | I11: 112 | J11: =G11-H11+I11
A12: Operating income | B12: OperatingIncomeLoss | C12: 5802 | D12: 6098 | E12: 6650 | F12: 6741 | G12: 8706 | H12: 6445 | I12: 7010 | J12: =G12-H12+I12
A13: Nonoperating income (expense), net | B13: NonoperatingIncomeExpense | C13: -97 | D13: -90 | E13: 149 | F13: 190 | G13: 28 | H13: 25 | I13: 7 | J13: =G13-H13+I13
A14: Income before taxes | B14: IncomeLossFromContinuingOperationsBeforeIncomeTaxes... | C14: 5705 | D14: 6008 | E14: 6799 | F14: 6931 | G14: 8734 | H14: 6470 | I14: 7017 | J14: =G14-H14+I14
A15: Income tax expense | B15: IncomeTaxExpenseBenefit | C15: 883 | D15: 1252 | E15: 1371 | F15: 1371 | G15: 1604 | H15: 1196 | I15: 1589 | J15: =G15-H15+I15
A16: Net income | B16: NetIncomeLoss | C16: 4822 | D16: 4756 | E16: 5428 | F16: 5560 | G16: 7130 | H16: 5274 | I16: 5428 | J16: =G16-H16+I16
A17: Diluted weighted-average shares | B17: WeightedAverageNumberOfDilutedSharesOutstanding (9M = mean of quarters) | C17: 481 | D17: 470.9 | E17: 459.1 | F17: 449.7 | G17: 427 | H17: 430.2 | I17: 402.9 | J17: =G17
A18: Diluted EPS (GAAP) | C18: =C16/C17 | D18: =D16/D17 | E18: =E16/E17 | F18: =F16/F17 | G18: =G16/G17 | H18: =H16/H17 | I18: =I16/I17 | J18: =J16/J17
A20: Depreciation & amortization (CF stmt) | B20: DepreciationDepletionAndAmortization | C20: 788 | D20: 856 | E20: 872 | F20: 857 | G20: 818 | H20: 634 | I20: 582 | J20: =G20-H20+I20
A21: Stock-based compensation | B21: ShareBasedCompensation | C21: 1069 | D21: 1440 | E21: 1718 | F21: 1833 | G21: 1942 | H21: 1453 | I21: 1582 | J21: =G21-H21+I21
A22: Cash flow from operations | B22: NetCashProvidedByUsedInOperatingActivities | C22: 7230 | D22: 7838 | E22: 7302 | F22: 8056 | G22: 10031 | H22: 6871 | I22: 7646 | J22: =G22-H22+I22
A23: Capital expenditures | B23: PaymentsToAcquirePropertyPlantAndEquipment | C23: 348 | D23: 442 | E23: 360 | F23: 183 | G23: 179 | H23: 145 | I23: 180 | J23: =G23-H23+I23
A24: Common stock repurchases | B24: PaymentsForRepurchaseOfCommonStock | C24: 3950 | D24: 6550 | E24: 4400 | F24: 9500 | G24: 11281 | H24: 8807 | I24: 6821 | J24: =G24-H24+I24
A25: Free cash flow (CFO − capex) | C25: =C22-C23 | D25: =D22-D23 | E25: =E22-E23 | F25: =F22-F23 | G25: =G22-G23 | H25: =H22-H23 | I25: =I22-I23 | J25: =J22-J23
A26: EBITDA (operating income + D&A) | C26: =C12+C20 | D26: =D12+D20 | E26: =E12+E20 | F26: =F12+F20 | G26: =G12+G20 | H26: =H12+H20 | I26: =I12+I20 | J26: =J12+J20
A28: Cash & equivalents | B28: CashAndCashEquivalentsAtCarryingValue | C28: 3844 | D28: 4236 | E28: 7141 | F28: 7613 | G28: 5431 | K28: 4359
A29: Short-term investments | B29: ShortTermInvestments | C29: 1954 | D29: 1860 | E29: 701 | F29: 273 | G29: 1164 | K29: 1280
A30: Trade receivables, net | B30: AccountsReceivableNetCurrent | C30: 1878 | D30: 2065 | E30: 2224 | F30: 2072 | G30: 2344 | K30: 2081
A31: Total assets | B31: Assets | C31: 27241 | D31: 27165 | E31: 29779 | F31: 30230 | G31: 29496 | K31: 29981
A32: Long-term debt | B32: LongTermDebt | C32: 4123 | D32: 3629 | E32: 3634 | F32: 4129 | G32: 6210 | K32: 4766
A33: Current debt | B33: DebtCurrent | C33: 0 | D33: 500 | E33: 0 | F33: 1499 | G33: 0 | K33: 1597
A34: Deferred revenue (current) | B34: ContractWithCustomerLiabilityCurrent | C34: 4733 | D34: 5297 | E34: 5837 | F34: 6131 | G34: 6905 | K34: 7094
A35: Total liabilities | B35: Liabilities | C35: 12444 | D35: 13114 | E35: 13261 | F35: 16125 | G35: 17873 | K35: 18217
A36: Total stockholders' equity | B36: StockholdersEquity | C36: 14797 | D36: 14051 | E36: 16518 | F36: 14105 | G36: 11623 | K36: 11764
A37: Total debt (LT + current) | C37: =C32+C33 | D37: =D32+D33 | E37: =E32+E33 | F37: =F32+F33 | G37: =G32+G33 | K37: =K32+K33
A38: Shares outstanding (period end) | B38: dei EntityCommonStockSharesOutstanding — 10-K cover dates for FY23–FY25; Q3 FY26 10-Q cover (Sep 18, 2026) in Latest column | E38: 452 | F38: 435.3 | G38: 410.5 | K38: 389.2

Sheet Assumptions
A1: Assumptions — every yellow cell is an input; the rationale is stated next to it
A3: Assumption | B3: Value | C3: Source / rationale
A4: MARKET (as of Oct 20, 2026)
A5: Share price — close, Mon Oct 19, 2026 ($) | B5: 247.09 | C5: MarketBeat price history and Finnhub quote, retrieved Oct 20, 2026; corroborated by stockanalysis.com (close Oct 19, 2026, 4:00 PM ET). Stooq CSV was JS-blocked.
A6: Shares outstanding (M) — Sep 18, 2026 | B6: 389.2 | C6: SEC EDGAR dei EntityCommonStockSharesOutstanding, Q3 FY2026 10-Q cover (filed Sep 22, 2026). Market cap at the close: $96.2B (247.09 × 389.2M).
A7: Net debt at Q3 FY26 ($M) — debt less cash & ST investments | B7: =Historicals!K37-Historicals!K28-Historicals!K29 | C7: Formula from Historicals (Q3 FY2026 balance sheet, Aug 28, 2026): total debt $6,363M − cash $4,359M − ST investments $1,280M = $724M net debt — Adobe is essentially net-debt neutral.
A9: Q4 FY2026E BUILD — FY2026E = 9M FY2026 actual + Q4 estimate. Q4 FY2025A is derived (FY2025 − 9M FY2025, formulas).
B10: Q4 FY25A | C10: Growth / input | D10: Q4 FY26E | E10: Rationale
A11: Revenue | B11: =Historicals!G5-Historicals!H5 | C11: 0.12 | D11: =B11*(1+C11) | E11: Q1–Q3 FY26 grew +12.0%/+12.7%/+12.9% YoY; Q4 guided confidently (non-GAAP EPS guide $6.30–6.35). I use +12.0% — no further acceleration assumed.
A12: Cost of revenue | B12: =Historicals!G6-Historicals!H6 | C12: 0.13 | D12: =B12*(1+C12) | E12: AI inference/hosting costs growing slightly faster than revenue, as in 9M FY26 (CoR +13% YoY).
A13: Research & development | B13: =Historicals!G8-Historicals!H8 | C13: 0.12 | D13: =B13*(1+C13) | E13: In line with 9M FY26 R&D growth (+13% YoY) and continued Firefly/AI investment.
A14: Sales & marketing | B14: =Historicals!G9-Historicals!H9 | C14: 0.11 | D14: =B14*(1+C14) | E14: Below revenue growth — modest leverage, consistent with 9M FY26.
A15: General & administrative | B15: =Historicals!G10-Historicals!H10 | C15: 0.05 | D15: =B15*(1+C15) | E15: G&A ran hot in 9M FY26 (+13% YoY on deal/legal costs); I normalize Q4 growth to +5%.
A16: Amortization of acquired intangibles | B16: =Historicals!G11-Historicals!H11 | D16: 40 | E16: Derived IS amortization was $157M in FY2025 and is declining as acquired intangibles roll off (9M FY26: ~$112M); Q4 stub of $40M.
A17: Nonoperating income, net | B17: =Historicals!G13-Historicals!H13 | D17: 45 | E17: Interest income on ~$5.6B cash/STI roughly offsets interest on $6.4B of notes; 9M FY26 net was +$7M.
A18: Stock-based compensation | B18: =Historicals!G21-Historicals!H21 | D18: 520 | E18: Q4 FY25 SBC was $485M (FY25 $1,938M − 9M $1,453M); +7% YoY in line with headcount/comp drift.
A19: Depreciation & amortization (CF) | B19: =Historicals!G20-Historicals!H20 | D19: 210 | E19: 9M FY26 D&A was $582M (EDGAR YTD); Q4 run-rate ~$200M/quarter.
A20: Capital expenditures | B20: =Historicals!G23-Historicals!H23 | D20: 55 | E20: Capex is minimal at Adobe (FY25: $183M, 0.8% of revenue); 9M FY26 was $180M incl. facilities fit-out.
A21: Common stock repurchases | B21: =Historicals!G24-Historicals!H24 | D21: 2600 | E21: 9M FY26 repurchases were $6,821M (~$2.3B/qtr); Q4 is seasonally the largest FCF quarter — $2.6B assumed.
A22: Q4 FY26E effective tax rate | B22: 0.19 | C22: Q4 FY25 ETR was ~28% on discrete items; 9M FY26 ETR was 22.6%. I use 19% for the Q4 stub — near the FY25 full-year rate of 18.3%.
A23: Q4 FY26E diluted shares (M) | B23: 383 | C23: Share count fell from 410.8M (Q1 WA) to 395.5M (Q3 WA) during FY26; Q4 buybacks continue the decline.
A25: FORECAST DRIVERS — FY2026E / FY2027E / FY2028E
B26: FY26E | C26: FY27E | D26: FY28E | E26: Rationale
A27: Trade receivables, % of revenue | B27: 0.097 | C27: 0.097 | D27: 0.097 | E27: FY25 actual: 9.9% of revenue (receivables are seasonally highest at the Nov year-end). Held flat.
A28: Deferred revenue (current) growth | B28: 0.1 | C28: 0.1 | D28: 0.1 | E28: Deferred revenue grew +12.7% in FY25 and tracks subscription bookings; I grow it slightly below revenue growth.
A29: Total debt, year-end ($M) | B29: 6250 | E29: FY26E year-end input: Q3 FY26 actual total debt was $6,363M; assumes ~$113M net repayment in Q4. FY27E/FY28E use the change row below.
A30: Total debt change ($M) | C30: -250 | D30: -250 | E30: Maturing notes repaid from cash flow; no new issuance assumed — Adobe has no funding need.
A31: Average repurchase price ($) | B31: 265 | C31: 300 | D31: 340 | E31: Blended FY26 average ~$265 (the stock fell through the year: Q3 10-Q cover count implies heavy H2 buying at lower prices); FY27/28 assume prices recover toward — but stay below — my target, which is conservative for share-count decline.
A32: Shares issued for equity comp (M) | B32: 6 | C32: 6 | D32: 6 | E32: Gross issuance under equity plans before repurchases; roughly offsets ~15% of the buyback share reduction.
A33: Revenue growth | C33: 0.11 | D33: 0.105 | E33: FY26E grows +12.4% (9M actual + Q4E). I fade growth slowly — +11.0%, then +10.5% — below the FY26 run-rate; no AI-driven re-acceleration is assumed, which keeps the pitch honest.
A34: Gross margin | C34: 0.892 | D34: 0.893 | E34: FY25: 89.3%; 9M FY26: 89.2%. AI inference costs pressure, mix (Document Cloud, enterprise) offsets. Held ~flat.
A35: R&D, % of revenue | C35: 0.18 | D35: 0.179 | E35: FY25: 18.0%; 9M FY26: 18.2%. AI product investment stays elevated; slight leverage by FY28.
A36: Sales & marketing, % of revenue | C36: 0.27 | D36: 0.267 | E36: FY25: 27.3%; 9M FY26: 27.4%. Modest leverage as self-serve/PLG mix grows.
A37: General & administrative, % of revenue | C37: 0.068 | D37: 0.067 | E37: FY25: 6.6%; 9M FY26 ran at 7.6% (deal/legal costs). I normalize toward ~6.7–6.8%.
A38: Amortization of acquired intangibles ($M) | C38: 150 | D38: 140 | E38: Declining schedule as acquired intangibles roll off (derived IS line: FY25 $157M; FY26E ~$152M).
A39: Interest rate on beginning debt | C39: 0.041 | D39: 0.041 | E39: Blended coupon: FY25 implied interest was ~$220M on ~$5.4B average debt (nonoperating net +$28M vs other income +$248M).
A40: Interest yield on beginning cash & STI | C40: 0.038 | D40: 0.038 | E40: Money-market/T-bill yields on the cash pile, net of other nonoperating items.
A41: Effective tax rate | C41: 0.185 | D41: 0.185 | E41: FY25 ETR: 18.3%; FY23–FY25 range 18–21%. I use 18.5%.
A42: Stock-based compensation, % of revenue | C42: 0.078 | D42: 0.076 | E42: FY25: 8.2% of revenue; 9M FY26: 8.0%. Slow improvement assumed — SBC is the single biggest GAAP/non-GAAP gap and a real cost I do not add back in the DCF.
A43: Depreciation & amortization, CF stmt ($M) | C43: 800 | D43: 790 | E43: FY25: $820M; declining as the asset base seasons. Note: D&A here is the cash-flow-statement line (incl. intangible amortization).
...

Sheet IS
A1: Income Statement — actual FY2025 and forecast FY2026E–FY2028E ($M, except per-share)
B3: FY2025A | C3: FY2026E | D3: FY2027E | E3: FY2028E
A4: Revenue | C4: =Historicals!G5 | D4: =Historicals!I5+Assumptions!$D$11 | E4: =D4*(1+Assumptions!$C$33) | F4: =E4*(1+Assumptions!$D$33)
A5: Cost of revenue | C5: =Historicals!G6 | D5: =Historicals!I6+Assumptions!$D$12 | E5: =E4*(1-Assumptions!$C$34) | F5: =F4*(1-Assumptions!$D$34)
A6: Gross profit | C6: =C4-C5 | D6: =D4-D5 | E6: =E4-E5 | F6: =F4-F5
A7: Research & development | C7: =Historicals!G8 | D7: =Historicals!I8+Assumptions!$D$13 | E7: =E4*Assumptions!$C$35 | F7: =F4*Assumptions!$D$35
A8: Sales & marketing | C8: =Historicals!G9 | D8: =Historicals!I9+Assumptions!$D$14 | E8: =E4*Assumptions!$C$36 | F8: =F4*Assumptions!$D$36
A9: General & administrative | C9: =Historicals!G10 | D9: =Historicals!I10+Assumptions!$D$15 | E9: =E4*Assumptions!$C$37 | F9: =F4*Assumptions!$D$37
A10: Amortization of acquired intangibles | C10: =Historicals!G11 | D10: =Historicals!I11+Assumptions!$D$16 | E10: =Assumptions!$C$38 | F10: =Assumptions!$D$38
A11: Operating income | C11: =C6-C7-C8-C9-C10 | D11: =D6-D7-D8-D9-D10 | E11: =E6-E7-E8-E9-E10 | F11: =F6-F7-F8-F9-F10
A12: Interest expense | D12: 0 | E12: ='CF_BS'!D28*Assumptions!$C$39 | F12: ='CF_BS'!E28*Assumptions!$D$39
A13: Nonoperating income (expense), net | C13: =Historicals!G13 | D13: =Historicals!I13+Assumptions!$D$17 | E13: =('CF_BS'!D22+'CF_BS'!D23)*Assumptions!$C$40 | F13: =('CF_BS'!E22+'CF_BS'!E23)*Assumptions!$D$40
A14: Income before taxes | C14: =C11+C13 | D14: =D11+D13 | E14: =E11-E12+E13 | F14: =F11-F12+F13
A15: Income tax expense | C15: =Historicals!G15 | D15: =Historicals!I15+(D14-Historicals!I14)*Assumptions!$B$22 | E15: =E14*Assumptions!$C$41 | F15: =F14*Assumptions!$D$41
A16: Net income | C16: =C14-C15 | D16: =D14-D15 | E16: =E14-E15 | F16: =F14-F15
A17: Diluted weighted-average shares | C17: =Historicals!G17 | D17: =(Historicals!I17*9+Assumptions!$B$23*3)/12 | E17: ='CF_BS'!E41 | F17: ='CF_BS'!F41
A18: Diluted EPS (GAAP) | C18: =C16/C17 | D18: =D16/D17 | E18: =E16/E17 | F18: =F16/F17
A19: Memo: non-GAAP EPS proxy (NI + SBC + amort. of acquired intangibles, pre-tax) | C19: =(C16+Historicals!G21+C10)/C17 | D19: =(D16+'CF_BS'!D7+D10)/D17 | E19: =(E16+'CF_BS'!E7+E10)/E17 | F19: =(F16+'CF_BS'!F7+F10)/F17
A21: Notes: (1) FY2025A interest expense is not broken out in EDGAR company facts after FY2023 — it sits inside nonoperating income, net; forecast years split interest expense (on beginning debt) and interest/other income (on beginning cash & ST investments) explicitly. (2) Adobe guides on a non-GAAP basis (FY2026 guide: $24.45–$24.50, per the Q3 FY26 release). The proxy above adds back SBC and acquired-intangible amortization pre-tax, so it overstates slightly vs Adobe's tax-effected non-GAAP EPS — it is a reasonableness check on the forecast, not a replication of Adobe's non-GAAP definition.

Sheet CF_BS
A1: Cash Flow & Balance Sheet — linked forecast ($M). The balance sheet balances by construction: every balance-sheet delta appears once in the cash flow, and equity rolls with net income + SBC − buybacks.
B3: FY2025A | C3: FY2026E | D3: FY2027E | E3: FY2028E
A5: Net income | C5: =IS!C16 | D5: =IS!D16 | E5: =IS!E16 | F5: =IS!F16
A6: Plus: depreciation & amortization | C6: =Historicals!G20 | D6: =Historicals!I20+Assumptions!$D$19 | E6: =Assumptions!$C$43 | F6: =Assumptions!$D$43
A7: Plus: stock-based compensation | C7: =Historicals!G21 | D7: =Historicals!I21+Assumptions!$D$18 | E7: =IS!E4*Assumptions!$C$42 | F7: =IS!F4*Assumptions!$D$42
A8: Less: increase in trade receivables | D8: =-(D24-C24) | E8: =-(E24-D24) | F8: =-(F24-E24)
A9: Plus: increase in deferred revenue | D9: =D29-C29 | E9: =E29-D29 | F9: =F29-E29
A10: Plus: increase in other liabilities | D10: =D30-C30 | E10: =E30-D30 | F10: =F30-E30
A11: Cash flow from operations | C11: =Historicals!G22 | D11: =SUM(D5:D7)+D8+D9+D10 | E11: =SUM(E5:E7)+E8+E9+E10 | F11: =SUM(F5:F7)+F8+F9+F10
A12: Capital expenditures | C12: =Historicals!G23 | D12: =Historicals!I23+Assumptions!$D$20 | E12: =IS!E4*Assumptions!$C$44 | F12: =IS!F4*Assumptions!$D$44
A13: Free cash flow | C13: =C11-C12 | D13: =D11-D12 | E13: =E11-E12 | F13: =F11-F12
A14: Increase in short-term investments | D14: 0 | E14: 0 | F14: 0
A15: Common stock repurchases | C15: =Historicals!G24 | D15: =Historicals!I24+Assumptions!$D$21 | E15: =Assumptions!$C$45 | F15: =Assumptions!$D$45
A16: Net debt issued (repaid) | D16: =D28-C28 | E16: =Assumptions!$C$30 | F16: =Assumptions!$D$30
A17: Change in cash | D17: =D11-D12-D14-D15+D16 | E17: =E11-E12-E14-E15+E16 | F17: =F11-F12-F14-F15+F16
A18: Cash, beginning of year | D18: =C22 | E18: =D22 | F18: =E22
A19: Cash, end of year | C19: =Historicals!G28 | D19: =D18+D17 | E19: =E18+E17 | F19: =F18+F17
A21: BALANCE SHEET
A22: Cash & equivalents | C22: =C19 | D22: =D19 | E22: =E19 | F22: =F19
A23: Short-term investments | C23: =Historicals!G29 | D23: =C23+D14 | E23: =D23+E14 | F23: =E23+F14
A24: Trade receivables, net | C24: =Historicals!G30 | D24: =IS!D4*Assumptions!$B$27 | E24: =IS!E4*Assumptions!$C$27 | F24: =IS!F4*Assumptions!$D$27
A25: Other assets (incl. PP&E, goodwill, intangibles) | C25: =Historicals!G31-C22-C23-C24 | D25: =C25+D12-D6 | E25: =D25+E12-E6 | F25: =E25+F12-F6
A26: Total assets | C26: =SUM(C22:C25) | D26: =SUM(D22:D25) | E26: =SUM(E22:E25) | F26: =SUM(F22:F25)
A28: Total debt | C28: =Historicals!G37 | D28: =Assumptions!$B$29 | E28: =D28+E16 | F28: =E28+F16
A29: Deferred revenue (current) | C29: =Historicals!G34 | D29: =C29*(1+Assumptions!$B$28) | E29: =D29*(1+Assumptions!$C$28) | F29: =E29*(1+Assumptions!$D$28)
A30: Other liabilities (incl. deferred revenue, non-current) | C30: =Historicals!G35-C28-C29 | D30: =C30*(IS!D4/IS!C4) | E30: =D30*(IS!E4/IS!D4) | F30: =E30*(IS!F4/IS!E4)
A31: Total liabilities | C31: =SUM(C28:C30) | D31: =SUM(D28:D30) | E31: =SUM(E28:E30) | F31: =SUM(F28:F30)
A32: Total stockholders' equity | C32: =Historicals!G36 | D32: =C32+D5+D7-D15 | E32: =D32+E5+E7-E15 | F32: =E32+F5+F7-F15
A33: Total liabilities & equity | C33: =C31+C32 | D33: =D31+D32 | E33: =E31+E32 | F33: =F31+F32
A34: BALANCE CHECK (assets − L&E; must be 0) | C34: =C26-C33 | D34: =D26-D33 | E34: =E26-E33 | F34: =F26-F33
A36: SHARE COUNT ROLL (millions)
A37: Shares outstanding, beginning | D37: =Historicals!G38 | E37: =D40 | F37: =E40
A38: Less: shares repurchased | D38: =D15/Assumptions!$B$31 | E38: =E15/Assumptions!$C$31 | F38: =F15/Assumptions!$D$31
A39: Plus: shares issued for equity comp | D39: =Assumptions!$B$32 | E39: =Assumptions!$C$32 | F39: =Assumptions!$D$32
A40: Shares outstanding, end of year | D40: =D37-D38+D39 | E40: =E37-E38+E39 | F40: =F37-F38+F39
A41: Diluted weighted-average shares (BS roll) | E41: =(E37+E40)/2 | F41: =(F37+F40)/2
A43: Cross-check: the roll implies ~381M shares at FY26 year-end vs 389.2M actually outstanding at Sep 18, 2026 with a full quarter of buybacks still to run — consistent. FY2025A cash-flow column shows reported figures; forecast columns are fully formula-driven.

Sheet Valuation
A1: Valuation — DCF (base / bear / bull / disruption), multiples cross-check, sensitivity
A3: CURRENT MULTIPLES (at $247.09, Oct 19, 2026 close)
A4: Market capitalization ($M) | B4: =Assumptions!$B$5*Assumptions!$B$6
A5: Plus: net debt at Q3 FY26 ($M) | B5: =Assumptions!$B$7
A6: Enterprise value ($M) | B6: =B4+B5
A7: LTM revenue ($M) | B7: =Historicals!J5
A8: LTM EBITDA ($M) | B8: =Historicals!J26
A9: LTM free cash flow ($M) | B9: =Historicals!J25
A10: EV / LTM EBITDA | B10: =Valuation!$B$6/Valuation!$B$8
A11: Price / LTM FCF | B11: =Valuation!$B$4/Valuation!$B$9
A12: P / E (LTM GAAP) | B12: =Assumptions!$B$5/Historicals!J18
A14: OWN-HISTORY MULTIPLES — market cap at calendar year-end (companiesmarketcap.com) vs that fiscal year's fundamentals (EDGAR). FY ends late Nov/early Dec, so the calendar year-end cap is the nearest trading day after the fiscal year-end.
A15: Fiscal year | B15: Year-end mkt cap ($M) | C15: Net debt at FY-end ($M) | D15: EV ($M) | E15: EBITDA ($M) | F15: FCF ($M) | G15: EV/EBITDA | H15: P/FCF
A16: FY2021 | B16: 269350 | C16: =Historicals!C37-Historicals!C28-Historicals!C29 | D16: =B16+C16 | E16: =Historicals!C26 | F16: =Historicals!C25 | G16: =D16/E16 | H16: =B16/F16
A17: FY2022 | B17: 156450 | C17: =Historicals!D37-Historicals!D28-Historicals!D29 | D17: =B17+C17 | E17: =Historicals!D26 | F17: =Historicals!D25 | G17: =D17/E17 | H17: =B17/F17
A18: FY2023 | B18: 271630 | C18: =Historicals!E37-Historicals!E28-Historicals!E29 | D18: =B18+C18 | E18: =Historicals!E26 | F18: =Historicals!E25 | G18: =D18/E18 | H18: =B18/F18
A19: FY2024 | B19: 196540 | C19: =Historicals!F37-Historicals!F28-Historicals!F29 | D19: =B19+C19 | E19: =Historicals!F26 | F19: =Historicals!F25 | G19: =D19/E19 | H19: =B19/F19
A20: FY2025 | B20: 150080 | C20: =Historicals!G37-Historicals!G28-Historicals!G29 | D20: =B20+C20 | E20: =Historicals!G26 | F20: =Historicals!G25 | G20: =D20/E20 | H20: =B20/F20
A21: Median FY21–FY25 | G21: =MEDIAN(G16:G20) | H21: =MEDIAN(H16:H20)
A23: DCF — BASE CASE (FCF FY2027E–FY2031E; FY27/28 from the three-statement model, FY29–31 fade at assumption growth rates)
B24: FY27E | C24: FY28E | D24: FY29E | E24: FY30E | F24: FY31E
A25: Free cash flow ($M) | B25: ='CF_BS'!E13 | C25: ='CF_BS'!F13 | D25: =C25*(1+Assumptions!$B$60) | E25: =D25*(1+Assumptions!$B$61) | F25: =E25*(1+Assumptions!$B$62)
A26: Discount factor | B26: =1/(1+Valuation!$B$29)^1 | C26: =1/(1+Valuation!$B$29)^2 | D26: =1/(1+Valuation!$B$29)^3 | E26: =1/(1+Valuation!$B$29)^4 | F26: =1/(1+Valuation!$B$29)^5
A27: PV of FCF | B27: =B25*B26 | C27: =C25*C26 | D27: =D25*D26 | E27: =E25*E26 | F27: =F25*F26
A28: PV of FY27E–31E FCF ($M) | B28: =SUM(B27:F27)
A29: WACC | B29: =Assumptions!$B$56
A30: Terminal growth | B30: =Assumptions!$B$57
A31: Terminal value ($M) | B31: =F25*(1+Valuation!$B$30)/(Valuation!$B$29-Valuation!$B$30)
A32: PV of terminal value ($M) | B32: =B31*F26
A33: Enterprise value ($M) | B33: =Valuation!$B$28+Valuation!$B$32
A34: Less: net debt ($M) | B34: =Assumptions!$B$7
A35: Equity value ($M) | B35: =B33-B34
A36: Diluted shares out (M) | B36: =Assumptions!$B$6
A37: TARGET PRICE | B37: =B35/B36
A38: Current price | B38: =Assumptions!$B$5
A39: Implied upside | B39: =B37/B38-1
A41: SCENARIOS (same FCF base unless shocked; disruption uses its own FCF path)
A42: Scenario | B42: FCF FY27E | C42: FCF FY28E | D42: FCF FY29E | E42: FCF FY30E | F42: FCF FY31E | G42: WACC | H42: Term. g | I42: Equity value ($M) | J42: Per share | K42: Upside
A43: Base | B43: =B25 | C43: =C25 | D43: =D25 | E43: =E25 | F43: =F25 | G43: =Valuation!$B$29 | H43: =Valuation!$B$30 | I43: =B43/(1+$G43)^1+C43/(1+$G43)^2+D43/(1+$G43)^3+E43/(1+$G43)^4+F43/(1+$G43)^5+F43*(1+H43)/(G43-H43)/(1+G43)^5-Assumptions!$B$7 | J43: =I43/Assumptions!$B$6 | K43: =J43/Assumptions!$B$5-1
A44: Bear (FCF −18%, WACC +50bp, g 2.5%) | B44: =B25*(1+Assumptions!$B$63) | C44: =C25*(1+Assumptions!$B$63) | D44: =D25*(1+Assumptions!$B$63) | E44: =E25*(1+Assumptions!$B$63) | F44: =F25*(1+Assumptions!$B$63) | G44: =Valuation!$B$29+Assumptions!$B$64 | H44: =Assumptions!$B$65 | I44: =B44/(1+$G44)^1+C44/(1+$G44)^2+D44/(1+$G44)^3+E44/(1+$G44)^4+F44/(1+$G44)^5+F44*(1+H44)/(G44-H44)/(1+G44)^5-Assumptions!$B$7 | J44: =I44/Assumptions!$B$6 | K44: =J44/Assumptions!$B$5-1
...
